<?xml version="1.0" encoding="utf-8"?>
<!-- This URDF was automatically created by SolidWorks to URDF Exporter! Originally created by Stephen Brawner (brawner@gmail.com) 
     Commit Version: 1.6.0-4-g7f85cfe  Build Version: 1.6.7995.38578
     For more information, please see http://wiki.ros.org/sw_urdf_exporter -->
<robot
  name="四足v6">
  <link
    name="base_link">
    <inertial>
      <origin
        xyz="0.037901 -0.003961 -0.092021"
        rpy="0 0 0" />
      <mass
        value="21.745430" />
      <inertia
        ixx="0.410730"
        ixy="0.011332"
        ixz="0.069267"
        iyy="1.635269"
        iyz="-0.008477"
        izz="1.558092" />
    </inertial>
    <visual>
      <origin
        xyz="0 0 0"
        rpy="0 0 0" />
      <geometry>
        <mesh
          filename="package://四足v6/meshes/base_link.STL" />
      </geometry>
      <material
        name="">
        <color
          rgba="1 1 1 1" />
      </material>
    </visual>
    <collision>
      <origin
        xyz="0 0 -0.095"
        rpy="0 0 0" />
      <geometry>
        <box size="0.7 0.32 0.18" />
      </geometry>
    </collision>
  </link>
  <link
    name="FL_hip">
    <inertial>
      <origin
        xyz="0.084784 0.050221 -0.000527"
        rpy="0 0 0" />
      <mass
        value="1.873954" />
      <inertia
        ixx="0.007525"
        ixy="-0.008284"
        ixz="0.000080"
        iyy="0.018151"
        iyz="0.000064"
        izz="0.021589" />
    </inertial>
    <visual>
      <origin
        xyz="0 0 0"
        rpy="0 0 0" />
      <geometry>
        <mesh
          filename="package://四足v6/meshes/FL_hip.STL" />
      </geometry>
      <material
        name="">
        <color
          rgba="1 1 1 1" />
      </material>
    </visual>
    <collision>
      <origin
        xyz="0.09 0.05 0"
        rpy="1.5707963267948966 0 0" />
      <geometry>
        <cylinder length="0.06" radius="0.055" />
      </geometry>
    </collision>
  </link>
  <joint
    name="FL_hip_joint"
    type="revolute">
    <origin
      xyz="0.337 0.09 -0.09"
      rpy="0 0 0" />
    <parent
      link="base_link" />
    <child
      link="FL_hip" />
    <axis
      xyz="-1 0 0" />
    <limit
      lower="-0.65"
      upper="0.65"
      effort="0"
      velocity="0" />
  </joint>
  <link
    name="FL_thigh">
    <inertial>
      <origin
        xyz="-0.277638 0.028572 -0.045571"
        rpy="0 0 0" />
      <mass
        value="2.397110" />
      <inertia
        ixx="0.010858"
        ixy="0.021159"
        ixz="-0.036606"
        iyy="0.226928"
        iyz="0.003553"
        izz="0.221349" />
    </inertial>
    <visual>
      <origin
        xyz="0 0 0"
        rpy="0 0 0" />
      <geometry>
        <mesh
          filename="package://四足v6/meshes/FL_thigh.STL" />
      </geometry>
      <material
        name="">
        <color
          rgba="1 1 1 1" />
      </material>
    </visual>
    <collision>
      <origin
        xyz="-0.17 0.029 -0.03"
        rpy="0 -0.15 0" />
      <geometry>
        <box size="0.35 0.035 0.05" />
      </geometry>
    </collision>
  </link>
  <joint
    name="FL_thigh_joint"
    type="revolute">
    <origin
      xyz="0.0895 0.079 0"
      rpy="0 0 0" />
    <parent
      link="FL_hip" />
    <child
      link="FL_thigh" />
    <axis
      xyz="0 -1 0" />
    <limit
      lower="0"
      upper="0"
      effort="0"
      velocity="0" />
  </joint>
  <link
    name="FL_calf">
    <inertial>
      <origin
        xyz="0.257100 0.028947 0.028340"
        rpy="0 0 0" />
      <mass
        value="1.776471" />
      <inertia
        ixx="0.005341"
        ixy="-0.015063"
        ixz="-0.017919"
        iyy="0.148506"
        iyz="-0.001853"
        izz="0.147183" />
    </inertial>
    <visual>
      <origin
        xyz="0 0 0"
        rpy="0 0 0" />
      <geometry>
        <mesh
          filename="package://四足v6/meshes/FL_calf.STL" />
      </geometry>
      <material
        name="">
        <color
          rgba="1 1 1 1" />
      </material>
    </visual>
    <collision>
      <origin
        xyz="0.15 0.018 0"
        rpy="0 1.57 0" />
      <geometry>
        <cylinder length="0.35" radius="0.025" />
      </geometry>
    </collision>
  </link>
  <joint
    name="FL_calf_joint"
    type="revolute">
    <origin
      xyz="-0.34418 0.05829 -0.059482"
      rpy="0 0 0" />
    <parent
      link="FL_thigh" />
    <child
      link="FL_calf" />
    <axis
      xyz="0 -1 0" />
    <limit
      lower="0"
      upper="0"
      effort="0"
      velocity="0" />
  </joint>
  <link
    name="FL_foot">
    <inertial>
      <origin
        xyz="0.000000 0.032660 0.000000"
        rpy="0 0 0" />
      <mass
        value="1.485719" />
      <inertia
        ixx="0.005505"
        ixy="0.000000"
        ixz="0.000000"
        iyy="0.007569"
        iyz="0.000000"
        izz="0.005505" />
    </inertial>
    <visual>
      <origin
        xyz="0 0 0"
        rpy="0 0 0" />
      <geometry>
        <mesh
          filename="package://四足v6/meshes/FL_foot.STL" />
      </geometry>
      <material
        name="">
        <color
          rgba="1 1 1 1" />
      </material>
    </visual>
    <collision>
      <origin
        xyz="0 0.03 0"
        rpy="1.5707963267948966 0 0" />
      <geometry>
        <cylinder length="0.048" radius="0.1085" />
      </geometry>
    </collision>
  </link>
  <joint
    name="FL_foot_joint"
    type="continuous">
    <origin
      xyz="0.34592 0.06371 0.047982"
      rpy="0 0 0" />
    <parent
      link="FL_calf" />
    <child
      link="FL_foot" />
    <axis
      xyz="0 -1 0" />
  </joint>
  <link
    name="FR_hip">
    <inertial>
      <origin
        xyz="0.084784 -0.050221 -0.000527"
        rpy="0 0 0" />
      <mass
        value="1.873954" />
      <inertia
        ixx="0.007525"
        ixy="0.008284"
        ixz="0.000080"
        iyy="0.018151"
        iyz="-0.000064"
        izz="0.021589" />
    </inertial>
    <visual>
      <origin
        xyz="0 0 0"
        rpy="0 0 0" />
      <geometry>
        <mesh
          filename="package://四足v6/meshes/FR_hip.STL" />
      </geometry>
      <material
        name="">
        <color
          rgba="0.79216 0.81961 0.93333 1" />
      </material>
    </visual>
    <collision>
      <origin
        xyz="0.09 -0.05 0"
        rpy="1.5707963267948966 0 0" />
      <geometry>
        <cylinder length="0.06" radius="0.055" />
      </geometry>
    </collision>
  </link>
  <joint
    name="FR_hip_joint"
    type="revolute">
    <origin
      xyz="0.337 -0.09 -0.09"
      rpy="0 0 0" />
    <parent
      link="base_link" />
    <child
      link="FR_hip" />
    <axis
      xyz="-1 0 0" />
    <limit
      lower="-0.65"
      upper="0.65"
      effort="0"
      velocity="0" />
  </joint>
  <link
    name="FR_thigh">
    <inertial>
      <origin
        xyz="-0.277637 -0.028573 -0.045571"
        rpy="0 0 0" />
      <mass
        value="2.397021" />
      <inertia
        ixx="0.010858"
        ixy="-0.021159"
        ixz="-0.036604"
        iyy="0.226920"
        iyz="-0.003553"
        izz="0.221340" />
    </inertial>
    <visual>
      <origin
        xyz="0 0 0"
        rpy="0 0 0" />
      <geometry>
        <mesh
          filename="package://四足v6/meshes/FR_thigh.STL" />
      </geometry>
      <material
        name="">
        <color
          rgba="0.89804 0.91765 0.92941 1" />
      </material>
    </visual>
    <collision>
      <origin
        xyz="-0.17 -0.029 -0.03"
        rpy="0 -0.15 0" />
      <geometry>
        <box size="0.35 0.035 0.05" />
      </geometry>
    </collision>
  </link>
  <joint
    name="FR_thigh_joint"
    type="revolute">
    <origin
      xyz="0.0895 -0.079 0"
      rpy="0 0 0" />
    <parent
      link="FR_hip" />
    <child
      link="FR_thigh" />
    <axis
      xyz="0 1 0" />
    <limit
      lower="0"
      upper="0"
      effort="0"
      velocity="0" />
  </joint>
  <link
    name="FR_calf">
    <inertial>
      <origin
        xyz="0.257737 -0.027737 0.028858"
        rpy="0 0 0" />
      <mass
        value="1.776471" />
      <inertia
        ixx="0.005272"
        ixy="0.014542"
        ixz="-0.018189"
        iyy="0.149141"
        iyz="0.001818"
        izz="0.147644" />
    </inertial>
    <visual>
      <origin
        xyz="0 0 0"
        rpy="0 0 0" />
      <geometry>
        <mesh
          filename="package://四足v6/meshes/FR_calf.STL" />
      </geometry>
      <material
        name="">
        <color
          rgba="0.77647 0.75686 0.73725 1" />
      </material>
    </visual>
    <collision>
      <origin
        xyz="0.15 -0.018 0"
        rpy="0 1.57 0" />
      <geometry>
        <cylinder length="0.35" radius="0.025" />
      </geometry>
    </collision>
  </link>
  <joint
    name="FR_calf_joint"
    type="revolute">
    <origin
      xyz="-0.34482 -0.0595 -0.06"
      rpy="0 0 0" />
    <parent
      link="FR_thigh" />
    <child
      link="FR_calf" />
    <axis
      xyz="0 1 0" />
    <limit
      lower="0"
      upper="0"
      effort="0"
      velocity="0" />
  </joint>
  <link
    name="FR_foot">
    <inertial>
      <origin
        xyz="0.000000 -0.032660 0.000000"
        rpy="0 0 0" />
      <mass
        value="1.485719" />
      <inertia
        ixx="0.005505"
        ixy="0.000000"
        ixz="0.000000"
        iyy="0.007569"
        iyz="0.000000"
        izz="0.005505" />
    </inertial>
    <visual>
      <origin
        xyz="0 0 0"
        rpy="0 0 0" />
      <geometry>
        <mesh
          filename="package://四足v6/meshes/FR_foot.STL" />
      </geometry>
      <material
        name="">
        <color
          rgba="0.79216 0.81961 0.93333 1" />
      </material>
    </visual>
    <collision>
      <origin
        xyz="0 -0.03 0"
        rpy="1.5707963267948966 0 0" />
      <geometry>
        <cylinder length="0.048" radius="0.1085" />
      </geometry>
    </collision>
  </link>
  <joint
    name="FR_foot_joint"
    type="continuous">
    <origin
      xyz="0.34655 -0.0625 0.0485"
      rpy="0 0 0" />
    <parent
      link="FR_calf" />
    <child
      link="FR_foot" />
    <axis
      xyz="0 1 0" />
  </joint>
  <link
    name="RL_hip">
    <inertial>
      <origin
        xyz="-0.084784 0.050221 -0.000527"
        rpy="0 0 0" />
      <mass
        value="1.873954" />
      <inertia
        ixx="0.007525"
        ixy="0.008284"
        ixz="-0.000080"
        iyy="0.018151"
        iyz="0.000064"
        izz="0.021589" />
    </inertial>
    <visual>
      <origin
        xyz="0 0 0"
        rpy="0 0 0" />
      <geometry>
        <mesh
          filename="package://四足v6/meshes/RL_hip.STL" />
      </geometry>
      <material
        name="">
        <color
          rgba="1 1 1 1" />
      </material>
    </visual>
    <collision>
      <origin
        xyz="-0.09 0.05 0"
        rpy="1.5707963267948966 0 0" />
      <geometry>
        <cylinder length="0.06" radius="0.055" />
      </geometry>
    </collision>
  </link>
  <joint
    name="RL_hip_joint"
    type="revolute">
    <origin
      xyz="-0.337 0.09 -0.09"
      rpy="0 0 0" />
    <parent
      link="base_link" />
    <child
      link="RL_hip" />
    <axis
      xyz="1 0 0" />
    <limit
      lower="-0.65"
      upper="0.65"
      effort="0"
      velocity="0" />
  </joint>
  <link
    name="RL_thigh">
    <inertial>
      <origin
        xyz="0.277637 0.028573 -0.045571"
        rpy="0 0 0" />
      <mass
        value="2.397021" />
      <inertia
        ixx="0.010858"
        ixy="-0.021159"
        ixz="0.036604"
        iyy="0.226920"
        iyz="0.003553"
        izz="0.221340" />
    </inertial>
    <visual>
      <origin
        xyz="0 0 0"
        rpy="0 0 0" />
      <geometry>
        <mesh
          filename="package://四足v6/meshes/RL_thigh.STL" />
      </geometry>
      <material
        name="">
        <color
          rgba="1 1 1 1" />
      </material>
    </visual>
    <collision>
      <origin
        xyz="0.17 0.029 -0.03"
        rpy="0 0.15 0" />
      <geometry>
        <box size="0.35 0.035 0.05" />
      </geometry>
    </collision>
  </link>
  <joint
    name="RL_thigh_joint"
    type="revolute">
    <origin
      xyz="-0.0895 0.079 0"
      rpy="0 0 0" />
    <parent
      link="RL_hip" />
    <child
      link="RL_thigh" />
    <axis
      xyz="0 -1 0" />
    <limit
      lower="0"
      upper="0"
      effort="0"
      velocity="0" />
  </joint>
  <link
    name="RL_calf">
    <inertial>
      <origin
        xyz="-0.257737 0.027737 0.028858"
        rpy="0 0 0" />
      <mass
        value="1.776471" />
      <inertia
        ixx="0.005272"
        ixy="0.014542"
        ixz="0.018189"
        iyy="0.149141"
        iyz="-0.001818"
        izz="0.147644" />
    </inertial>
    <visual>
      <origin
        xyz="0 0 0"
        rpy="0 0 0" />
      <geometry>
        <mesh
          filename="package://四足v6/meshes/RL_calf.STL" />
      </geometry>
      <material
        name="">
        <color
          rgba="1 1 1 1" />
      </material>
    </visual>
    <collision>
      <origin
        xyz="-0.15 0.018 0"
        rpy="0 1.57 0" />
      <geometry>
        <cylinder length="0.35" radius="0.025" />
      </geometry>
    </collision>
  </link>
  <joint
    name="RL_calf_joint"
    type="revolute">
    <origin
      xyz="0.34482 0.0595 -0.06"
      rpy="0 0 0" />
    <parent
      link="RL_thigh" />
    <child
      link="RL_calf" />
    <axis
      xyz="0 -1 0" />
    <limit
      lower="0"
      upper="0"
      effort="0"
      velocity="0" />
  </joint>
  <link
    name="RL_foot">
    <inertial>
      <origin
        xyz="0.000000 0.032660 0.000000"
        rpy="0 0 0" />
      <mass
        value="1.485719" />
      <inertia
        ixx="0.005505"
        ixy="0.000000"
        ixz="0.000000"
        iyy="0.007569"
        iyz="0.000000"
        izz="0.005505" />
    </inertial>
    <visual>
      <origin
        xyz="0 0 0"
        rpy="0 0 0" />
      <geometry>
        <mesh
          filename="package://四足v6/meshes/RL_foot.STL" />
      </geometry>
      <material
        name="">
        <color
          rgba="1 1 1 1" />
      </material>
    </visual>
    <collision>
      <origin
        xyz="0 0.03 0"
        rpy="1.5707963267948966 0 0" />
      <geometry>
        <cylinder length="0.048" radius="0.1085" />
      </geometry>
    </collision>
  </link>
  <joint
    name="RL_foot_joint"
    type="continuous">
    <origin
      xyz="-0.34655 0.0625 0.0485"
      rpy="0 0 0" />
    <parent
      link="RL_calf" />
    <child
      link="RL_foot" />
    <axis
      xyz="0 -1 0" />
  </joint>
  <link
    name="RR_hip">
    <inertial>
      <origin
        xyz="-0.084784 -0.050221 -0.000527"
        rpy="0 0 0" />
      <mass
        value="1.873954" />
      <inertia
        ixx="0.007525"
        ixy="-0.008284"
        ixz="-0.000080"
        iyy="0.018151"
        iyz="-0.000064"
        izz="0.021589" />
    </inertial>
    <visual>
      <origin
        xyz="0 0 0"
        rpy="0 0 0" />
      <geometry>
        <mesh
          filename="package://四足v6/meshes/RR_hip.STL" />
      </geometry>
      <material
        name="">
        <color
          rgba="1 1 1 1" />
      </material>
    </visual>
    <collision>
      <origin
        xyz="-0.09 -0.05 0"
        rpy="1.5707963267948966 0 0" />
      <geometry>
        <cylinder length="0.06" radius="0.055" />
      </geometry>
    </collision>
  </link>
  <joint
    name="RR_hip_joint"
    type="revolute">
    <origin
      xyz="-0.337 -0.09 -0.09"
      rpy="0 0 0" />
    <parent
      link="base_link" />
    <child
      link="RR_hip" />
    <axis
      xyz="1 0 0" />
    <limit
      lower="-0.65"
      upper="0.65"
      effort="0"
      velocity="0" />
  </joint>
  <link
    name="RR_thigh">
    <inertial>
      <origin
        xyz="0.277638 -0.028572 -0.045571"
        rpy="0 0 0" />
      <mass
        value="2.397110" />
      <inertia
        ixx="0.010858"
        ixy="0.021159"
        ixz="0.036606"
        iyy="0.226928"
        iyz="-0.003553"
        izz="0.221349" />
    </inertial>
    <visual>
      <origin
        xyz="0 0 0"
        rpy="0 0 0" />
      <geometry>
        <mesh
          filename="package://四足v6/meshes/RR_thigh.STL" />
      </geometry>
      <material
        name="">
        <color
          rgba="1 1 1 1" />
      </material>
    </visual>
    <collision>
      <origin
        xyz="0.17 -0.029 -0.03"
        rpy="0 0.15 0" />
      <geometry>
        <box size="0.35 0.035 0.05" />
      </geometry>
    </collision>
  </link>
  <joint
    name="RR_thigh_joint"
    type="revolute">
    <origin
      xyz="-0.0895 -0.079 0"
      rpy="0 0 0" />
    <parent
      link="RR_hip" />
    <child
      link="RR_thigh" />
    <axis
      xyz="0 1 0" />
    <limit
      lower="0"
      upper="0"
      effort="0"
      velocity="0" />
  </joint>
  <link
    name="RR_calf">
    <inertial>
      <origin
        xyz="-0.257737 -0.027737 0.028858"
        rpy="0 0 0" />
      <mass
        value="1.776471" />
      <inertia
        ixx="0.005272"
        ixy="-0.014542"
        ixz="0.018189"
        iyy="0.149141"
        iyz="0.001818"
        izz="0.147644" />
    </inertial>
    <visual>
      <origin
        xyz="0 0 0"
        rpy="0 0 0" />
      <geometry>
        <mesh
          filename="package://四足v6/meshes/RR_calf.STL" />
      </geometry>
      <material
        name="">
        <color
          rgba="1 1 1 1" />
      </material>
    </visual>
    <collision>
      <origin
        xyz="-0.15 -0.018 0"
        rpy="0 1.57 0" />
      <geometry>
        <cylinder length="0.35" radius="0.025" />
      </geometry>
    </collision>
  </link>
  <joint
    name="RR_calf_joint"
    type="revolute">
    <origin
      xyz="0.34482 -0.0595 -0.06"
      rpy="0 0 0" />
    <parent
      link="RR_thigh" />
    <child
      link="RR_calf" />
    <axis
      xyz="0 1 0" />
    <limit
      lower="0"
      upper="0"
      effort="0"
      velocity="0" />
  </joint>
  <link
    name="RR_foot">
    <inertial>
      <origin
        xyz="0.000000 -0.032660 0.000000"
        rpy="0 0 0" />
      <mass
        value="1.485719" />
      <inertia
        ixx="0.005505"
        ixy="0.000000"
        ixz="0.000000"
        iyy="0.007569"
        iyz="0.000000"
        izz="0.005505" />
    </inertial>
    <visual>
      <origin
        xyz="0 0 0"
        rpy="0 0 0" />
      <geometry>
        <mesh
          filename="package://四足v6/meshes/RR_foot.STL" />
      </geometry>
      <material
        name="">
        <color
          rgba="1 1 1 1" />
      </material>
    </visual>
    <collision>
      <origin
        xyz="0 -0.03 0"
        rpy="1.5707963267948966 0 0" />
      <geometry>
        <cylinder length="0.048" radius="0.1085" />
      </geometry>
    </collision>
  </link>
  <joint
    name="RR_foot_joint"
    type="continuous">
    <origin
      xyz="-0.34655 -0.0625 0.0485"
      rpy="0 0 0" />
    <parent
      link="RR_calf" />
    <child
      link="RR_foot" />
    <axis
      xyz="0 1 0" />
  </joint>
  <link
    name="R_camera">
    <inertial>
      <origin
        xyz="0.000653 -0.003343 -0.015893"
        rpy="0 0 0" />
      <mass
        value="0.130154" />
      <inertia
        ixx="0.000055"
        ixy="0.000000"
        ixz="0.000001"
        iyy="0.000135"
        iyz="-0.000008"
        izz="0.000101" />
    </inertial>
    <visual>
      <origin
        xyz="0 0 0"
        rpy="0 0 0" />
      <geometry>
        <mesh
          filename="package://四足v6/meshes/R_camera.STL" />
      </geometry>
      <material
        name="">
        <color
          rgba="0.75294 0.75294 0.75294 1" />
      </material>
    </visual>
    <collision>
      <origin
        xyz="0 0 0"
        rpy="0 0 0" />
      <geometry>
        <box size="0.015 0.01 0.008" />
      </geometry>
    </collision>
  </link>
  <joint
    name="R_camera_joint"
    type="fixed">
    <origin
      xyz="-0.51479 -0.00059005 -0.035774"
      rpy="-1.8914 0 1.5708" />
    <parent
      link="base_link" />
    <child
      link="R_camera" />
    <axis
      xyz="0 0 0" />
  </joint>
  <link
    name="R_lidar">
    <inertial>
      <origin
        xyz="0.000200 -0.000002 -0.020323"
        rpy="0 0 0" />
      <mass
        value="0.791513" />
      <inertia
        ixx="0.000651"
        ixy="0.000000"
        ixz="0.000006"
        iyy="0.000677"
        iyz="0.000000"
        izz="0.000418" />
    </inertial>
    <visual>
      <origin
        xyz="0 0 0"
        rpy="0 0 0" />
      <geometry>
        <mesh
          filename="package://四足v6/meshes/R_lidar.STL" />
      </geometry>
      <material
        name="">
        <color
          rgba="0.75294 0.75294 0.75294 1" />
      </material>
    </visual>
    <collision>
      <origin
        xyz="0 0 -0.015"
        rpy="0 0 0" />
      <geometry>
        <cylinder length="0.06" radius="0.035" />
      </geometry>
    </collision>
  </link>
  <joint
    name="R_lidar_joint"
    type="fixed">
    <origin
      xyz="-0.50738 0 -0.098185"
      rpy="0.91291 1.5708 -2.1176" />
    <parent
      link="base_link" />
    <child
      link="R_lidar" />
    <axis
      xyz="0 0 1" />
  </joint>
  <link
    name="F_camera">
    <inertial>
      <origin
        xyz="-0.000922 0.003220 -0.014839"
        rpy="0 0 0" />
      <mass
        value="0.020126" />
      <inertia
        ixx="0.000008"
        ixy="0.000000"
        ixz="0.000000"
        iyy="0.000020"
        iyz="0.000001"
        izz="0.000015" />
    </inertial>
    <visual>
      <origin
        xyz="0 0 0"
        rpy="0 0 0" />
      <geometry>
        <mesh
          filename="package://四足v6/meshes/F_camera.STL" />
      </geometry>
      <material
        name="">
        <color
          rgba="0.75294 0.75294 0.75294 1" />
      </material>
    </visual>
    <collision>
      <origin
        xyz="0 0 0"
        rpy="0 0 0" />
      <geometry>
        <box size="0.015 0.01 0.008" />
      </geometry>
    </collision>
  </link>
  <joint
    name="F_camera_joint"
    type="fixed">
    <origin
      xyz="0.51479 -0.00059101 -0.035774"
      rpy="-2.3029 0 -1.5708" />
    <parent
      link="base_link" />
    <child
      link="F_camera" />
    <axis
      xyz="0 0 0" />
  </joint>
  <link
    name="F_lidar">
    <inertial>
      <origin
        xyz="0.000200 -0.000707 -0.020311"
        rpy="0 0 0" />
      <mass
        value="0.791508" />
      <inertia
        ixx="0.000651"
        ixy="0.000000"
        ixz="0.000006"
        iyy="0.000677"
        iyz="-0.000009"
        izz="0.000418" />
    </inertial>
    <visual>
      <origin
        xyz="0 0 0"
        rpy="0 0 0" />
      <geometry>
        <mesh
          filename="package://四足v6/meshes/F_lidar.STL" />
      </geometry>
      <material
        name="">
        <color
          rgba="1 1 1 1" />
      </material>
    </visual>
    <collision>
      <origin
        xyz="0 0 -0.015"
        rpy="0 0 0" />
      <geometry>
        <cylinder length="0.06" radius="0.035" />
      </geometry>
    </collision>
  </link>
  <joint
    name="F_lidar_joint"
    type="fixed">
    <origin
      xyz="0.50738 0 -0.098185"
      rpy="-1.5533 1.5708 -1.5882" />
    <parent
      link="base_link" />
    <child
      link="F_lidar" />
    <axis
      xyz="0 0 0" />
  </joint>
</robot>